Workbook

Sheet PLANT Intake Coding
G1: =SUM(G3:G17059) -> 5255.85 | K1: =SUM(K3:K997) -> 8141.15 | L1: =SUM(L3:L997) -> 666
A2: Date | B2: Source | C2: Genus | D2: Cultivar | E2: ID # | F2: SKU | G2: Total Cost | H2: Location | I2: Status | J2: Unique ID | K2: MSRP | L2: QTY | M2: Pot Type | N2: Unit Cost | O2: Owner Email | P2: Photo
A3: 38202 | B3: Home Stock | C3: Begonia | D3: Angel Wing | E3: 1A | F3: =IFERROR(__xludf.DUMMYFUNCTION("ARRAYFORMULA( IF(ROW(B3:B3059)<3,"""", IF(LEN(B3:B3059)=0,"""", IFERROR( VLOOKUP(UPPER(TRIM(B3:B3059)), {'Plant KEY'!A:A,'Plant KEY'!B:B}, 2, FALSE), LET( n, UPPER(TRIM(B3:B3059)), clean, REGEXREPLACE(n,""[^A-Z]"",""""), "&" base, IF(REGEXMATCH(n,""\s""), LEFT(SUBSTITUTE(REGEXREPLACE(REGEXREPLACE(SUBSTITUTE(n,""-"","" ""),""\b(OF|THE|AND|A|AN)\b"",""""),""(^| )([A-Z])[A-Z]+"","" $2""),"" "",""""),3), LEFT(clean,2) ), keycodes,"&" UPPER('Plant KEY'!F:F), fallback, IF(REGEXMATCH(n,""\s""), LET(lastword,IFERROR(TRIM(MID(n,FIND(""☺"",SUBSTITUTE(n,"" "",""☺"",LEN(n)-LEN(SUBSTITUTE(n,"" "",""""))))+1,100)),n),LEFT(base,2)&MID(lastword,2,1)), LEFT(c"&"lean,3) ), IF(COUNTIF(keycodes,base)=0,base,IF(COUNTIF(keycodes,fallback)=0,fallback,LEFT(clean,4))) ) ) & IF(LEN(C3:C3059), ""-"" & IFERROR( VLOOKUP(UPPER(TRIM(C3:C3059)), {'Plant KEY'!C:C,'Plant KEY'!D:D}, "&"2, FALSE), LET( n, UPPER(TRIM(C3:C3059)), clean, REGEXREPLACE(n,""[^A-Z]"",""""), base, IF(REGEXMATCH(n,""\s""), LEFT(SUBSTITUTE(REGEXREPLACE(REGEXREPLACE(SUBSTITUTE(n,""-"","" ""),""\b(OF|THE|AND|"&"A|AN)\b"",""""),""(^| )([A-Z])[A-Z]+"","" $2""),"" "",""""),3), LEFT(clean,2) ), keycodes, UPPER('Plant KEY'!D:D), fallback, IF(REGEXMATCH(n,""\s""), LET(lastword,IFERROR(TRIM(MID(n,FIND("""&"☺"",SUBSTITUTE(n,"" "",""☺"",LEN(n)-LEN(SUBSTITUTE(n,"" "",""""))))+1,100)),n),LEFT(base,2)&MID(lastword,2,1)), LEFT(clean,3) ), IF(COUNTIF(keycodes,base)=0,base,IF(COUNTIF(keycodes,fallback)=0,fallback,LEFT(clean,4))) "&" ) ), """") & IF(LEN(D3:D3059), ""-"" & IFERROR( VLOOKUP(UPPER(TRIM(D3:D3059)), {'Plant KEY'!E:E,'Plant KEY'!F:F}, 2, FALSE), LET( n, UPPER(TRIM(D3:D3059)), clean, REGEXREPLACE(n,""[^A-Z]"",""""),"&" base, IF(REGEXMATCH(n,""\s""), LEFT(SUBSTITUTE(REGEXREPLACE(REGEXREPLACE(SUBSTITUTE(n,""-"","" ""),""\b(OF|THE|AND|A|AN)\b"",""""),""(^| )([A-Z])[A-Z]+"","" $2""),"" "",""""),3), LEFT(clean,2) ), "&" keycodes, UPPER('Plant KEY'!F:F), fallback, IF(REGEXMATCH(n,""\s""), LET(lastword,IFERROR(TRIM(MID(n,FIND(""☺"",SUBSTITUTE(n,"" "",""☺"",LEN(n)-LEN(SUBSTITUTE(n,"" "",""""))))+1,100)),n),LEFT(base,2)&MID(lastword,2"&",1)), LEFT(clean,3) ), IF(COUNTIF(keycodes,base)=0,base,IF(COUNTIF(keycodes,fallback)=0,fallback,LEFT(clean,4))) ) ), """") & IF(LEN(E3:E3059), ""-"" & UPPER(TRIM(E3:E3059)),"""") ) ) )"),"HS-BE-AW-1A") -> HS-BE-AW-1A | G3: 0 | J3: E87921 | L3: 1 | M3: ST-PO-12-NU-1 | N3: {=IF(LEN(B3:B3059)=0, "", IFERROR(G3:G3059 / L3:L3059, "") )} -> 0 | O3: starr8@rocketmail.com
B4: Home Stock | C4: Pothos | D4: Golden | E4: 1A | F4: =IFERROR(__xludf.DUMMYFUNCTION("""COMPUTED_VALUE"""),"HS-PO-GO-1A") -> HS-PO-GO-1A | G4: 0 | J4: 9C3687 | L4: 1 | N4: 0 | O4: starr8@rocketmail.com
B5: Home Stock | C5: Philodendron | D5: Heart Leaf | E5: 1A | F5: =IFERROR(__xludf.DUMMYFUNCTION("""COMPUTED_VALUE"""),"HS-PH-HL-1A") -> HS-PH-HL-1A | G5: 0 | J5: 851D91 | L5: 1 | M5: ST-PO-0-CU-1 | N5: 0 | O5: starr8@rocketmail.com
B6: Home Stock | C6: Philodendron | D6: Brasil | E6: 1A | F6: =IFERROR(__xludf.DUMMYFUNCTION("""COMPUTED_VALUE"""),"HS-PH-BRL-1A") -> HS-PH-BRL-1A | G6: 0 | J6: FB20D8 | L6: 1 | N6: 0 | O6: starr8@rocketmail.com
B7: Home Stock | C7: Pilea | D7: Peperomioides | E7: 1A | F7: =IFERROR(__xludf.DUMMYFUNCTION("""COMPUTED_VALUE"""),"HS-PI-PEP-1A") -> HS-PI-PEP-1A | G7: 0 | J7: 62867D | L7: 1 | N7: 0 | O7: starr8@rocketmail.com
A8: 45899 | B8: Home Stock | C8: Ctenanthe | D8: Burle Marxii | E8: 1A | F8: =IFERROR(__xludf.DUMMYFUNCTION("""COMPUTED_VALUE"""),"HS-CT-BM-1A") -> HS-CT-BM-1A | G8: 0 | J8: 59D755 | L8: 1 | M8: ST-PO-4-NU-1 | N8: 0 | O8: starr8@rocketmail.com
F9: =IFERROR(__xludf.DUMMYFUNCTION("""COMPUTED_VALUE"""),"")
B10: Home Stock | C10: Dracaena | D10: Snake Plant | E10: 1A | F10: =IFERROR(__xludf.DUMMYFUNCTION("""COMPUTED_VALUE"""),"HS-DR-SP-1A") -> HS-DR-SP-1A | G10: 0 | J10: D10239 | L10: 1 | N10: 0 | O10: starr8@rocketmail.com
A11: 45873 | B11: Facebook Marketplace | C11: Philodendron | D11: White Knight | E11: 1A | F11: =IFERROR(__xludf.DUMMYFUNCTION("""COMPUTED_VALUE"""),"FM-PH-WK-1A") -> FM-PH-WK-1A | G11: 15 | H11: Cash | I11: None | J11: 8F306F | K11: 0 | L11: 1 | M11: ST-PO-6-NU-1 | N11: 15 | O11: starr8@rocketmail.com
A12: 45872 | B12: Walmart | C12: Philodendron | D12: White Knight | E12: 1A | F12: =IFERROR(__xludf.DUMMYFUNCTION("""COMPUTED_VALUE"""),"WM-PH-WK-1A") -> WM-PH-WK-1A | G12: 19.97 | J12: 3A0A52 | L12: 1 | N12: 19.97 | O12: starr8@rocketmail.com
B13: Walmart | C13: Monstera | D13: Peru | E13: 1A | F13: =IFERROR(__xludf.DUMMYFUNCTION("""COMPUTED_VALUE"""),"WM-MA-PE-1A") -> WM-MA-PE-1A | G13: 7 | J13: C7E314 | L13: 1 | N13: 7 | O13: starr8@rocketmail.com
A14: 45873 | B14: The Lady Cove | C14: Philodendron | D14: Cream Splash | E14: 1A | F14: =IFERROR(__xludf.DUMMYFUNCTION("""COMPUTED_VALUE"""),"TLC-PH-CS-1A") -> TLC-PH-CS-1A | G14: 0 | J14: AA4996 | L14: 1 | N14: 0 | O14: starr8@rocketmail.com
A15: 45874 | B15: The Amazing Garden | C15: Adenium Obesum | D15: Desert Rose | E15: 1A | F15: =IFERROR(__xludf.DUMMYFUNCTION("""COMPUTED_VALUE"""),"TAG-AO-DR-1A") -> TAG-AO-DR-1A | G15: 0 | J15: B16039 | L15: 1 | N15: 0 | O15: starr8@rocketmail.com
A16: 45880 | B16: Fred Meyer | C16: Philodendron | D16: Golden Crocodile | E16: 1A | F16: =IFERROR(__xludf.DUMMYFUNCTION("""COMPUTED_VALUE"""),"FMY-PH-GC-1A") -> FMY-PH-GC-1A | G16: 16.99 | J16: 4546BE | L16: 1 | M16: ST-PO-6-NU-1 | N16: 16.99 | O16: starr8@rocketmail.com
A17: 45880 | B17: Fred Meyer | C17: Alocasia | D17: Regal Shield | E17: 1A | F17: =IFERROR(__xludf.DUMMYFUNCTION("""COMPUTED_VALUE"""),"FMY-AL-RSD-1A") -> FMY-AL-RSD-1A | G17: 10.99 | J17: 5DCD93 | L17: 1 | N17: 10.99 | O17: starr8@rocketmail.com
A18: 45880 | B18: Fred Meyer | C18: Alocasia | D18: Green Velvet Frydek | E18: 1A | F18: =IFERROR(__xludf.DUMMYFUNCTION("""COMPUTED_VALUE"""),"FMY-AL-GVF-1A") -> FMY-AL-GVF-1A | G18: 10.99 | J18: 66B4DB | L18: 1 | N18: 10.99 | O18: starr8@rocketmail.com
A19: 45880 | B19: Fred Meyer | C19: Monstera | D19: Deliciosa | E19: 1A | F19: =IFERROR(__xludf.DUMMYFUNCTION("""COMPUTED_VALUE"""),"FMY-MA-DE-1A") -> FMY-MA-DE-1A | G19: 10.99 | J19: D764EE | K19: 25 | L19: 1 | M19: ST-PO-6-NU-1 | N19: 10.99 | O19: starr8@rocketmail.com
A20: 45880 | B20: Fred Meyer | C20: Monstera | D20: Deliciosa | E20: 1A-2 | F20: =IFERROR(__xludf.DUMMYFUNCTION("""COMPUTED_VALUE"""),"FMY-MA-DE-1A-2") -> FMY-MA-DE-1A-2 | G20: 19.99 | J20: BA6B4C | L20: 1 | M20: ST-PO-6-NU-1 | N20: 19.99 | O20: starr8@rocketmail.com
A21: 45880 | B21: The Lady Cove | C21: Scindapsus | D21: Silver Splash | E21: 1A | F21: =IFERROR(__xludf.DUMMYFUNCTION("""COMPUTED_VALUE"""),"TLC-SC-SS-1A") -> TLC-SC-SS-1A | G21: 1 | J21: 1DD88F | L21: 1 | N21: 1 | O21: starr8@rocketmail.com
A22: 45870 | B22: Maggie Mae Plants | C22: Monstera | D22: Adansonii | E22: 1A | F22: =IFERROR(__xludf.DUMMYFUNCTION("""COMPUTED_VALUE"""),"MMP-MA-AD-1A") -> MMP-MA-AD-1A | G22: 1 | J22: D78BB8 | L22: 1 | N22: 1 | O22: starr8@rocketmail.com
A23: 45866 | B23: Orange Lake Nursery | C23: Monstera | D23: Adansonii | E23: 1A | F23: =IFERROR(__xludf.DUMMYFUNCTION("""COMPUTED_VALUE"""),"OLN-MA-AD-1A") -> OLN-MA-AD-1A | G23: 3.66 | H23: Credit Card | I23: 2163 | J23: DB15AC | L23: 1 | M23: ST-PO-0-PL-1 | N23: 3.66 | O23: starr8@rocketmail.com
A24: 45866 | B24: Orange Lake Nursery | C24: Philodendron | D24: White Princess | E24: 1A | F24: =IFERROR(__xludf.DUMMYFUNCTION("""COMPUTED_VALUE"""),"OLN-PH-WP-1A") -> OLN-PH-WP-1A | G24: 3.66 | H24: Credit Card | I24: 2163 | J24: 1A5668 | L24: 1 | M24: ST-PO-0-PL-1 | N24: 3.66 | O24: starr8@rocketmail.com
A25: 45866 | B25: Orange Lake Nursery | C25: Alternanthera | D25: Party Time | E25: 1A | F25: =IFERROR(__xludf.DUMMYFUNCTION("""COMPUTED_VALUE"""),"OLN-ALT-PT-1A") -> OLN-ALT-PT-1A | G25: 9.99 | H25: Credit Card | I25: 2163 | J25: 30FC62 | L25: 1 | M25: ST-PO-0-PL-1 | N25: 9.99 | O25: starr8@rocketmail.com
A26: 45866 | B26: Orange Lake Nursery | C26: Fittonia | D26: Red Flame | E26: 1A | F26: =IFERROR(__xludf.DUMMYFUNCTION("""COMPUTED_VALUE"""),"OLN-FI-RF-1A") -> OLN-FI-RF-1A | G26: 3.66 | H26: Credit Card | I26: 2163 | J26: C4919B | L26: 1 | M26: ST-PO-4-NU-1 | N26: 3.66 | O26: starr8@rocketmail.com
A27: 45902 | B27: Orange Lake Nursery | C27: Philodendron | D27: Strawberry Shake | E27: 1A | F27: =IFERROR(__xludf.DUMMYFUNCTION("""COMPUTED_VALUE"""),"OLN-PH-STS-1A") -> OLN-PH-STS-1A | G27: 52 | H27: Credit Card | I27: 1002 | J27: DD2EF3 | L27: 1 | M27: ST-PO-4-NU-1 | N27: 52 | O27: starr8@rocketmail.com
A28: 45902 | B28: Orange Lake Nursery | C28: Philodendron | D28: Snow Drift | E28: 1A | F28: =IFERROR(__xludf.DUMMYFUNCTION("""COMPUTED_VALUE"""),"OLN-PH-SD-1A") -> OLN-PH-SD-1A | G28: 16 | H28: Credit Card | I28: 1002 | J28: A09A6D | L28: 1 | M28: ST-PO-4-NU-1 | N28: 16 | O28: starr8@rocketmail.com
A29: 45871 | B29: Aura Rooted | C29: Philodendron | D29: White Princess | E29: 1A | F29: =IFERROR(__xludf.DUMMYFUNCTION("""COMPUTED_VALUE"""),"AR-PH-WP-1A") -> AR-PH-WP-1A | G29: 20.4 | J29: F323DF | L29: 1 | N29: 20.4 | O29: starr8@rocketmail.com
A30: 45871 | B30: Aura Rooted | C30: Alocasia | D30: Longiloba Mint | E30: 1A | F30: =IFERROR(__xludf.DUMMYFUNCTION("""COMPUTED_VALUE"""),"AR-AL-LM-1A") -> AR-AL-LM-1A | G30: 18.9 | J30: D4D950 | L30: 1 | N30: 18.9 | O30: starr8@rocketmail.com
A31: 45877 | B31: Zen Botanicals | C31: Senecio | D31: Haworthii | E31: 1A | F31: =IFERROR(__xludf.DUMMYFUNCTION("""COMPUTED_VALUE"""),"ZB-SE-HA-1A") -> ZB-SE-HA-1A | G31: 0 | J31: D8F201 | L31: 1 | N31: 0 | O31: starr8@rocketmail.com
A32: 45878 | B32: It's a Succulent Thang | C32: Philodendron | D32: Pink Princess | E32: 1A | F32: =IFERROR(__xludf.DUMMYFUNCTION("""COMPUTED_VALUE"""),"IST-PH-PP-1A") -> IST-PH-PP-1A | G32: 10.8 | J32: B46EF4 | L32: 1 | N32: 10.8 | O32: starr8@rocketmail.com
A33: 45878 | B33: It's a Succulent Thang | C33: Philodendron | D33: Green Congo Nuclear | E33: 1A | F33: =IFERROR(__xludf.DUMMYFUNCTION("""COMPUTED_VALUE"""),"IST-PH-GCN-1A") -> IST-PH-GCN-1A | G33: 25 | J33: F3374E | L33: 1 | M33: ST-PO-4-NU-1 | N33: 25 | O33: starr8@rocketmail.com
A34: 45882 | B34: Ts Garden Gems | C34: Hoya | D34: Golden Flame | E34: 1A | F34: =IFERROR(__xludf.DUMMYFUNCTION("""COMPUTED_VALUE"""),"TGG-HO-GF-1A") -> TGG-HO-GF-1A | G34: 0 | J34: 1E3D42 | L34: 1 | N34: 0 | O34: starr8@rocketmail.com
A35: 45882 | B35: Ts Garden Gems | C35: Hoya | D35: Publicalyx | E35: 1A | F35: =IFERROR(__xludf.DUMMYFUNCTION("""COMPUTED_VALUE"""),"TGG-HO-PU-1A") -> TGG-HO-PU-1A | G35: 5 | J35: C41DCD | L35: 1 | N35: 5 | O35: starr8@rocketmail.com
A36: 45886 | B36: Facebook Marketplace | C36: Monstera | D36: Deliciosa | E36: 1A | F36: =IFERROR(__xludf.DUMMYFUNCTION("""COMPUTED_VALUE"""),"FM-MA-DE-1A") -> FM-MA-DE-1A | G36: 5 | H36: Cash | I36: None | J36: BC6E95 | K36: 0 | L36: 1 | M36: ST-PO-0-CU-1 | N36: 5 | O36: starr8@rocketmail.com
A37: 45882 | B37: Amazon | C37: Philodendron | D37: Pink Princess | E37: 1A | F37: =IFERROR(__xludf.DUMMYFUNCTION("""COMPUTED_VALUE"""),"AM-PH-PP-1A") -> AM-PH-PP-1A | G37: 10.25 | J37: EABB58 | L37: 1 | N37: 10.25 | O37: starr8@rocketmail.com
A38: 45882 | B38: Amazon | C38: Philodendron | D38: White Wizard | E38: 1A | F38: =IFERROR(__xludf.DUMMYFUNCTION("""COMPUTED_VALUE"""),"AM-PH-WW-1A") -> AM-PH-WW-1A | G38: 10.25 | J38: A7877B | L38: 1 | N38: 10.25 | O38: starr8@rocketmail.com
A39: 45882 | B39: Amazon | C39: Philodendron | D39: Gloriosum | E39: 1A | F39: =IFERROR(__xludf.DUMMYFUNCTION("""COMPUTED_VALUE"""),"AM-PH-GL-1A") -> AM-PH-GL-1A | G39: 10.25 | J39: 367351 | L39: 1 | N39: 10.25 | O39: starr8@rocketmail.com
A40: 45882 | B40: Amazon | C40: Philodendron | D40: Birkin | E40: 1A | F40: =IFERROR(__xludf.DUMMYFUNCTION("""COMPUTED_VALUE"""),"AM-PH-BI-1A") -> AM-PH-BI-1A | G40: 10.25 | J40: EBE164 | L40: 1 | N40: 10.25 | O40: starr8@rocketmail.com
...

Sheet Repotting Estimates
A1: Date | B1: Customer Name | C1: Customer Contact | D1: Hourly Wage | E1: Est. Labor Hours | F1: Est. Labor Charge | G1: Est. Materials Charge | H1: Est. Total | I1: Notes | J1: U ID | K1: User Email
A2: 46140 | B2: Caroline Seitz | D2: 30 | E2: 0.5 | F2: 15 | G2: 6.41 | H2: 21.41 | J2: d52bf719 | K2: starr8@rocketmail.com

Sheet Repotting Estimate Line Items
A1: Date | B1: Plant Description | C1: Action | D1: Pot Used | E1: Soil Mix | F1: Pot Charge | G1: Soil Charge | H1: Total Charge | I1: Notes | J1: Estimate ID | K1: U ID
A2: 46140 | B2: Angel Wing Begonia | C2: Transplant | D2: MA-PO-4-SW-1 | E2: BS-SO-FRM-2 | F2: 5 | G2: 1.41 | H2: 6.41 | J2: d52bf719 | K2: 6dd87619

Sheet Repotting Jobs
A1: Date | B1: Customer Name | C1: Customer Contact | D1: Hourly Wage | E1: Labor Hours | F1: Labor Charge | G1: Materials Charge | H1: Total Job Charge | I1: Other Item Total | J1: Total Paid | K1: Grand Total | L1: Status | M1: Notes | N1: U ID | O1: User Email
A2: 46136 | B2: Jennifer Rockwell | C2: Facebook | D2: 25 | E2: 2.83 | F2: 70.75 | G2: 52.08 | H2: 122.83 | I2: 49 | J2: 171.83 | K2: 171.83 | L2: Complete | N2: 293FF1 | O2: starr8@rocketmail.com
A3: 46140 | B3: Caroline Seitz | C3: Facebook | D3: 30 | F3: 0 | G3: 0 | H3: 0 | K3: 0 | N3: 4f803159 | O3: starr8@rocketmail.com
A4: 46156 | B4: Kloey Downs | C4: 541-295-5854 | D4: 30 | E4: 0.5 | F4: 15 | G4: 5.16 | H4: 20.16 | K4: 20.16 | N4: 24878c7e | O4: starr8@rocketmail.com

Sheet Repotting Jobs Cost
A1: Date | B1: Customer Name | C1: Customer Contact | D1: Hourly Wage | E1: Labor Hours | F1: Labor Cost | G1: Materials Cost | H1: Total Job Cost | I1: Status | J1: Total Paid | K1: Grand Total | L1: Profit | M1: Margin | N1: Notes | O1: U ID | P1: User Email | Q1: Job ID
A2: 45771 | B2: Jennifer Rockwell | C2: Facebook | D2: 25 | E2: 2.83 | F2: 70.75 | G2: 16.72 | H2: 87.47 | I2: Complete | J2: 171.83 | K2: 171.83 | L2: 84.36 | M2: 49.1 | O2: 293FF1 | P2: starr8@rocketmail.com | Q2: 293FF1

Sheet Kristina Overhead
A1: Date | B1: Vendor | C1: Brand | D1: Category | E1: Description | F1: Qty | G1: Sub Tot | H1: Ship. | I1: Disc. | J1: Un. Cost | K1: Act. Tot | L1: Pmt. M. | M1: Card # | N1: Invoice # | O1: Notes / Project | P1: U ID | Q1: Owner Email | R1: Receipt
A2: 46099 | B2: Mazda Of Olympia | C2: Subaru Forrester Wilderness | D2: Company Vehicle | E2: Company Vehicle | F2: 1 | G2: 18759 | I2: 0 | J2: 18759 | K2: 18759 | L2: Debit Card | M2: 4269 | P2: a4407819 | Q2: peakprecisionflooring@gmail.com
A3: 46102 | B3: Lumber Liquidators | C3: Coreluxe Flooring | D3: Floor Install | E3: Bedroom, hallway | F3: 14 | G3: 761.74 | I3: 0 | J3: 54.41 | K3: 761.74 | L3: Debit Card | M3: 4269 | N3: 43545 | O3: Home project | P3: 2fdbb9bf | Q3: peakprecisionflooring@gmail.com | R3: Blooming Starr Receipts/2fdbb9bf.Receipt.164010.jpg
A4: 46090 | B4: State Of Washington | C4: Peak precision flooring llc | D4: Licenses & Fees | E4: Liscencing | F4: 1 | G4: 108.11 | I4: 0 | J4: 108.11 | K4: 108.11 | L4: Debit Card | M4: 4269 | P4: 4031dfc4 | Q4: peakprecisionflooring@gmail.com

Sheet Repotting Line Items
A1: Date | B1: Plant Description | C1: Action | D1: Pot Used | E1: Soil Mix | F1: Pot Charge | G1: Soil Charge | H1: Total Charge | I1: Notes | J1: Job ID | K1: U ID
A2: 46136 | B2: Cactus | C2: Transplant | D2: LO-PO-3.7-CD-1 | E2: BS-SO-CA-1 | F2: 10 | G2: 1.31 | H2: 11.31 | J2: 293FF1 | K2: fdd322d0
A3: 46136 | B3: Snake Plant Rooted Cutting | C3: Plant | D3: TO-PO-4-MU-1 | E3: BS-SO-CA-1 | F3: 5 | G3: 1.41 | H3: 6.41 | I3: Purple Pot | J3: 293FF1 | K3: 49d69e7f
A4: 46136 | B4: Spider Plant | C4: Transplant | D4: ST-PO-6-COP-1 | E4: BS-SO-FRM-2 | F4: 0 | G4: 5.16 | H4: 5.16 | J4: 293FF1 | K4: 0ca7eb0f
A5: 46136 | B5: Syngonium 1 | C5: Tran/Div | D5: NR-PO-5-BP-1 | E5: BS-SO-ACM-5 | F5: 12 | G5: 4.22 | H5: 16.22 | J5: 293FF1 | K5: 5524d4b4
A6: 46136 | B6: Syngonium 2 | C6: Tran/Div | D6: MU-PO-4-WH-1 | E6: BS-SO-ACM-5 | F6: 5 | G6: 1.41 | H6: 6.41 | I6: White Pot | J6: 293FF1 | K6: 20873e5f
A7: 46136 | B7: Aloe Vera | C7: Transplant | D7: ST-PO-4-COP-1 | E7: BS-SO-CA-1 | F7: 0 | G7: 1.41 | H7: 1.41 | J7: 293FF1 | K7: 7b816b8a
A8: 46136 | B8: Snake Plant | C8: Transplant | D8: ST-PO-6-COP-1 | E8: BS-SO-CA-1 | F8: 0 | G8: 5.16 | H8: 5.16 | J8: 293FF1 | K8: 3afb867f
A9: 46156 | B9: Pothos | C9: Transplant | D9: ST-PO-6-NU-1 | E9: BS-SO-ACM-7 | F9: 0 | G9: 5.16 | H9: 5.16 | J9: 24878c7e | K9: 97adb881

Sheet Plant KEY
A1: Sources | B1: Code | C1: Genus | D1: Code | E1: Cultivars | F1: Code | G1: Card Number | H1: ID # | I1: Payment Method
A2: Arcadia Garden Products | B2: AGP | C2: Acer | D2: AC | E2: Adansonii | F2: AD | G2: 0590 | H2: 1A | I2: ACH
A3: Amazon | B3: AM | C3: Adenium Obesum | D3: AO | E3: Angel Wing | F3: AW | G3: 1002 | H3: 1A-2 | I3: Credit Card
A4: Facebook Marketplace | B4: FM | C4: Blechnum | D4: BL | E4: Beauty Star | F4: BS | G4: 3150 | H4: 1A-7 | I4: Cash
A5: Brandon The Plant Guy | B5: BTPG | C5: Alternanthera | D5: ALT | E5: Birkin | F5: BI | G5: 5770 | H5: 1A-4 | I5: Cash App
A6: Best Plant Friend | B6: BPF | C6: Alocasia | D6: AL | E6: Bisma Dragon Scale | F6: BDS | G6: 6116 | H6: 1A-3 | I6: Other
A7: Aura Rooted | B7: AR | C7: Aglaonema | D7: AG | E7: Black Cardinal | F7: BC | G7: 9565 | H7: 1A-6 | I7: PayPal
A8: Dicks Sticks & Exotics | B8: DSE | C8: Begonia | D8: BE | E8: Brasil | F8: BRL | G8: UI | I8: Square
A9: Ed Hume | B9: EH | C9: Chamaedorea | D9: CHA | E9: Burle Marx Variegated | F9: BMV | G9: 6921 | H9: 1A-5 | I9: Venmo
A10: My Plants LLC | B10: MPL | C10: Asplenium | D10: ASP | E10: Burle Marxii | F10: BM | H10: 1A-8 | I10: Zelle
A11: The Rooted Plant Shop | B11: RPS | C11: Aeschynanthus | D11: AE | E11: Carnosa | F11: CA | H11: 1A-9 | I11: Promotional Credit
A12: Succulents and Such | B12: SS | C12: Allium | D12: ALL | E12: Common Lilac | F12: CL | I12: Gift Certificate
A13: Tactiko | B13: TA | C13: Aloe | D13: ALO | E13: Cream Splash | F13: CS | H13: 1A-10 | I13: Debit Card
A14: The Green Escape | B14: TGE | C14: Anthurium | D14: AN | E14: Crocatum | F14: CR | H14: 1A-11 | I14: Unpaid Invoice
A15: Home Stock | B15: HS | C15: Cymbopogon | D15: CY | E15: Deliciosa | F15: DE
A16: Fred Meyer | B16: FMY | C16: Farfuglum | D16: FA | E16: Desert Rose | F16: DR | H16: 1A-12
A17: It's a Succulent Thang | B17: IST | C17: Neanthe | D17: NE | E17: Diamond | F17: DI | H17: 1A-13
A18: Jumanji Jon Plants | B18: JJP | C18: Ocimum | D18: OC | E18: Domesticum | F18: DO | H18: 1A-14
A19: Land Of Alice | B19: LOA | C19: Origanum | D19: OR | E19: Dottie | F19: DOT | H19: 1A-15
A20: Micro Cultivate | B20: MI | C20: Pinguicula | D20: PIN | E20: Elegans | F20: EL | H20: 1B
A21: Maggie Mae Plants | B21: MMP | C21: Rhaphidophora | D21: RH | E21: Florida Bronze | F21: FB | H21: 1C
A22: Orange Lake Nursery | B22: OLN | C22: Salvia | D22: SAL | E22: Fusion White | F22: FW | H22: 1H
A23: The Green Escape | B23: TGE | C23: Thymus | D23: TH | E23: Gloriosum | F23: GL
A24: Palm Street | B24: PS | C24: Tomato | D24: TO | E24: Golden | F24: GO | H24: 1D
A25: Rooted Summerville | B25: RSV | C25: Fittonia | D25: FI | E25: Golden Crocodile | F25: GC | H25: 1E
A26: The Amazing Garden | B26: TAG | C26: Hoya | D26: HO | E26: Golden Flame | F26: GF | H26: 1F
A27: Thorsen's Greenhouse | B27: TG | C27: Hurricane | D27: HU | E27: Golden Girl | F27: GG | H27: 1G
A28: The Gay Ole Plant Shop | B28: TGOPS | C28: Hydrangea | D28: HY | E28: Gollum Jade | F28: GJ | H28: 1I
A29: Totally Rooted LLC | B29: TRL | C29: Maranta | D29: MAR | E29: Green Congo Nuclear | F29: GCN | H29: 1J
A30: TikTok | B30: TT | C30: Monstera | D30: MA | E30: Green Velvet Frydek | F30: GVF | H30: 1K
A31: Zen Botanicals | B31: ZB | C31: Philodendron | D31: PH | E31: Haworthii | F31: HA
A32: Walmart | B32: WM | C32: Pilea | D32: PI | E32: Heart Leaf | F32: HL | H32: 1M
A33: The Lady Cove | B33: TLC | C33: Philodendron Hederaceum | D33: PHH | E33: Japanese Maple | F33: JM | H33: 1L
A34: Ts Garden Gems | B34: TGG | C34: Piper | D34: PIP | E34: Jose Buono | F34: JB | H34: 1N
A35: BWH Plant Company | B35: BWH | C35: Pothos | D35: PO | E35: Krimson Princess | F35: KP | H35: 1O
A36: Fontanimal Plant House | B36: FPH | C36: Scindapsus | D36: SC | E36: Lacecap | F36: LC | H36: 1P
A37: Home Depot | B37: HD | C37: Sensation Aurea | D37: SA | E37: Leuconeura Lemon | F37: LL | H37: 1R
A38: Dell Road | B38: DR | C38: Senecio | D38: SE | E38: Longiloba | F38: LO | H38: 1Q
C39: Stromanthe | D39: ST | E39: Longiloba Mint | F39: LM
C40: Syngonium | D40: SYN | E40: Makoyana | F40: MA | H40: 1S
...

Sheet Plant Inventory
A2: Date | B2: SKU | C2: Product Name | D2: Plant Cost | E2: Plant MSRP | F2: Est. Sale Price | G2: Act. Sell Price | H2: Profit | I2: Margin | J2: Status | K2: Notes | L2: U ID | M2: QTY Purchased | N2: QTY Sold | O2: QTY Used | P2: QTY Remaining | Q2: Owner Email | R2: Other Cost | S2: Total Cost | T2: Photo | U2: Other MSRP | V2: Total MSRP
A3: 42181 | B3: HS-CHL-SPI-1A | C3: Chlorophytum Spider Plant | D3: 0 | E3: 0 | J3: Status Pending | L3: XUZG6O | M3: 1 | N3: 0 | O3: 0 | P3: 1 | Q3: starr8@rocketmail.com | R3: 0 | S3: 0 | U3: 0
A4: 42181 | B4: HS-CHL-SPI-1A-2 | C4: Chlorophytum Spider Plant | D4: 0 | E4: 0 | J4: Status Pending | L4: OTJGIB | M4: 1 | N4: 0 | O4: 0 | P4: 1 | Q4: starr8@rocketmail.com | R4: 0 | S4: 0 | U4: 0
A5: 45866 | B5: OLN-FI-RF-1A | C5: Fittonia Red Flame | D5: 3.66 | E5: 0 | J5: Status Pending | L5: 39X0FM | M5: 1 | N5: 0 | O5: 0 | P5: 1 | Q5: starr8@rocketmail.com | R5: 0 | S5: 3.66 | U5: 0.25 | V5: 0.25
A6: 45873 | B6: TLC-PH-CS-1A | C6: Philodendron Cream Splash | D6: 0 | E6: 0 | J6: Status Pending | L6: WHQ1FG | M6: 1 | N6: 0 | O6: 0 | P6: 1 | Q6: starr8@rocketmail.com | R6: 0 | S6: 0 | U6: 0
A7: 45880 | B7: FMY-AL-RSD-1A | C7: Alocasia Regal Shield | D7: 10.99 | E7: 0 | F7: 40 | H7: 29.01 | I7: 0.72525 | J7: For Sale | L7: YSRDV1 | M7: 1 | N7: 0 | O7: 0 | P7: 1 | Q7: starr8@rocketmail.com | R7: 0 | S7: 10.99 | U7: 0
A8: 45881 | B8: TGOPS-PH-POO-1A-2 | C8: Philodendron Prince of Orange | D8: 7.79 | E8: 12.99 | J8: Status Pending | L8: WWGDIW | M8: 1 | N8: 0 | O8: 0 | P8: 1 | Q8: starr8@rocketmail.com | R8: 0 | S8: 7.79 | U8: 0 | V8: 12.99
A9: 45885 | B9: HS-PO-GO-1H | C9: Pothos Golden | D9: 0 | E9: 0 | J9: Status Pending | L9: NUMDI0 | M9: 1 | N9: 0 | O9: 0 | P9: 1 | Q9: starr8@rocketmail.com | R9: 0.92 | S9: 0.92 | U9: 0
A10: 45885 | B10: HS-PH-HL-1B | C10: Philodendron Heart Leaf | D10: 0 | E10: 0 | J10: Status Pending | L10: MV58CR | M10: 1 | N10: 0 | O10: 0 | P10: 1 | Q10: starr8@rocketmail.com | R10: 0.5 | S10: 0.5 | U10: 5 | V10: 5
A11: 45886 | B11: FM-MA-DE-1A | C11: Monstera Deliciosa | D11: 5 | E11: 0 | J11: Status Pending | L11: WD7WRM | M11: 1 | N11: 0 | O11: 0 | P11: 1 | Q11: starr8@rocketmail.com | R11: 0 | S11: 5 | U11: 0
A12: 45886 | B12: HD-PH-GG-1A | C12: Philodendron Golden Girl | D12: 19.98 | E12: 0 | J12: Status Pending | L12: AJGH01 | M12: 1 | N12: 0 | O12: 0 | P12: 1 | Q12: starr8@rocketmail.com | R12: 0 | S12: 19.98 | U12: 0
A13: 45886 | B13: HD-HO-SSS-1A | C13: Hoya Shining Sea Star | D13: 19.98 | E13: 0 | J13: Not for Sale | L13: 4QPCZJ | M13: 1 | N13: 0 | O13: 0 | P13: 1 | Q13: starr8@rocketmail.com | R13: 0 | S13: 19.98 | U13: 0
A14: 45886 | B14: HD-AL-LO-1B | C14: Alocasia Longiloba | D14: 7.5 | E14: 0 | F14: 25 | H14: 16.08 | I14: 0.6432 | J14: For Sale | L14: 0581CE | M14: 1 | N14: 0 | O14: 0 | P14: 1 | Q14: starr8@rocketmail.com | R14: 1.42 | S14: 8.92 | U14: 0
A15: 45888 | B15: HS-PI-PEP-1C | C15: Pilea Peperomioides | D15: 0 | E15: 0 | J15: Status Pending | L15: ADNJZH | M15: 1 | N15: 0 | O15: 0 | P15: 1 | Q15: starr8@rocketmail.com | R15: 0.29 | S15: 0.29 | U15: 0
A16: 45889 | B16: BWH-PH-RAPK-1A-3 | C16: Philodendron Red Anderson Pink Knight | D16: 10.2 | E16: 24.99 | F16: 30 | H16: 18.45 | I16: 0.615 | J16: For Sale | L16: JNFAYP | M16: 1 | N16: 0 | O16: 0 | P16: 1 | Q16: starr8@rocketmail.com | R16: 1.35 | S16: 11.55 | U16: 0 | V16: 24.99
A17: 45889 | B17: BWH-PH-RAPK-1A-4 | C17: Philodendron Red Anderson Pink Knight | D17: 10.2 | E17: 24.99 | J17: Status Pending | L17: N3BIB5 | M17: 1 | N17: 0 | O17: 0 | P17: 1 | Q17: starr8@rocketmail.com | R17: 1.35 | S17: 11.55 | U17: 0 | V17: 24.99
A18: 45890 | B18: HS-PI-PEP-1B | C18: Pilea Peperomioides | D18: 0 | E18: 0 | F18: 45 | H18: 44.71 | I18: 0.99355556 | J18: Status Pending | L18: 28327B | M18: 1 | N18: 0 | O18: 0 | P18: 1 | Q18: starr8@rocketmail.com | R18: 0.29 | S18: 0.29 | U18: 0
A19: 45890 | B19: BWH-PO-PAJ-1A-4A | C19: Pothos Pearls and Jade | D19: 1.95 | E19: 4.25 | J19: Status Pending | L19: G3NJBQ | M19: 1 | N19: 0 | O19: 0 | P19: 1 | Q19: starr8@rocketmail.com | R19: 0.92 | S19: 2.87 | U19: 0 | V19: 4.25
A20: 45890 | B20: BWH-PH-MO-1A-4 | C20: Philodendron Moonlight | D20: 6 | E20: 12.99 | J20: Status Pending | L20: Q34PVG | M20: 1 | N20: 0 | O20: 0 | P20: 1 | Q20: starr8@rocketmail.com | R20: 0.5 | S20: 6.5 | U20: 5 | V20: 17.99
A21: 45890 | B21: TGE-COL-DI-1A | C21: Colocasia Diamond | D21: 12.5 | E21: 0 | J21: Status Pending | L21: IEVN04 | M21: 1 | N21: 0 | O21: 0 | P21: 1 | Q21: starr8@rocketmail.com | R21: 0 | S21: 12.5 | U21: 0
A22: 45891 | B22: FMY-MA-DE-1A-3 | C22: Monstera Deliciosa | D22: 3.33 | E22: 0 | J22: Status Pending | L22: 7782F2 | M22: 1 | N22: 0 | O22: 0 | P22: 1 | Q22: starr8@rocketmail.com | R22: 0.5 | S22: 3.83 | U22: 5 | V22: 5
A23: 45891 | B23: FMY-MA-DE-1A-5 | C23: Monstera Deliciosa | D23: 2.75 | E23: 0 | J23: Status Pending | L23: GPYXM3 | M23: 1 | N23: 0 | O23: 0 | P23: 1 | Q23: starr8@rocketmail.com | R23: 1.35 | S23: 4.1 | U23: 0
A24: 45891 | B24: FMY-MA-DE-1A-4C | C24: Monstera Deliciosa | D24: 1.57 | E24: 0 | J24: Status Pending | L24: HL79I0 | M24: 1 | N24: 0 | O24: 0 | P24: 1 | Q24: starr8@rocketmail.com | R24: 0.5 | S24: 2.07 | U24: 5 | V24: 5
A25: 45891 | B25: FMY-MA-DE-1A-4D | C25: Monstera Deliciosa | D25: 1.57 | E25: 0 | J25: Status Pending | L25: 2MDRWW | M25: 1 | N25: 0 | O25: 0 | P25: 1 | Q25: starr8@rocketmail.com | R25: 0.5 | S25: 2.07 | U25: 5 | V25: 5
A26: 45891 | B26: FMY-MA-DE-1A-4F | C26: Monstera Deliciosa | D26: 1.57 | E26: 0 | F26: 20 | H26: 17.51 | I26: 0.8755 | J26: Status Pending | L26: CE12DE | M26: 1 | N26: 0 | O26: 0 | P26: 1 | Q26: starr8@rocketmail.com | R26: 0.92 | S26: 2.49 | U26: 0
A27: 45891 | B27: FMY-MA-DE-1A-3A | C27: Monstera Deliciosa | D27: 3.33 | E27: 0 | J27: Status Pending | L27: CX628U | M27: 1 | N27: 0 | O27: 0 | P27: 1 | Q27: starr8@rocketmail.com | R27: 1.06 | S27: 4.39 | U27: 5 | V27: 5
A28: 45891 | B28: FMY-MA-DE-1A-3B | C28: Monstera Deliciosa | D28: 3.33 | E28: 0 | J28: Status Pending | L28: 15ZW4Q | M28: 1 | N28: 0 | O28: 0 | P28: 1 | Q28: starr8@rocketmail.com | R28: 1.06 | S28: 4.39 | U28: 5 | V28: 5
A29: 45891 | B29: FMY-MA-DE-1A-3D | C29: Monstera Deliciosa | D29: 3.33 | E29: 0 | J29: Status Pending | L29: PNO518 | M29: 1 | N29: 0 | O29: 0 | P29: 1 | Q29: starr8@rocketmail.com | R29: 1.06 | S29: 4.39 | U29: 5 | V29: 5
A30: 45891 | B30: FMY-MA-DE-1A-3E | C30: Monstera Deliciosa | D30: 3.33 | E30: 0 | J30: Status Pending | L30: D8ZBCX | M30: 1 | N30: 0 | O30: 0 | P30: 1 | Q30: starr8@rocketmail.com | R30: 0.29 | S30: 3.62 | U30: 0
A31: 45892 | B31: HD-AL-GVF-1A-2 | C31: Alocasia Green Velvet Frydek | D31: 14.99 | E31: 0 | J31: Status Pending | L31: SNAZUL | M31: 1 | N31: 0 | O31: 0 | P31: 1 | Q31: starr8@rocketmail.com | R31: 1.35 | S31: 16.34 | U31: 0
A32: 45892 | B32: HD-ST-TR-1A | C32: Stromanthe Triostar | D32: 19.98 | E32: 0 | J32: Status Pending | L32: H43F16 | M32: 1 | N32: 0 | O32: 0 | P32: 1 | Q32: starr8@rocketmail.com | R32: 0.61 | S32: 20.59 | U32: 5 | V32: 5
A33: 45892 | B33: IST-PH-PP-1B | C33: Philodendron Pink Princess | D33: 5.4 | E33: 0 | J33: Status Pending | L33: PHIQRY | M33: 1 | N33: 0 | O33: 0 | P33: 1 | Q33: starr8@rocketmail.com | R33: 0.13 | S33: 5.53 | U33: 0
A34: 45892 | B34: IST-PH-PP-1C | C34: Philodendron Pink Princess | D34: 5.4 | E34: 0 | J34: Status Pending | L34: UKSX6B | M34: 1 | N34: 0 | O34: 0 | P34: 1 | Q34: starr8@rocketmail.com | R34: 0.13 | S34: 5.53 | U34: 0
A35: 45892 | B35: HD-AL-GVF-1A-2B | C35: Alocasia Green Velvet Frydek | D35: 14.99 | E35: 0 | J35: Status Pending | L35: BJTOC6 | M35: 1 | N35: 0 | O35: 0 | P35: 1 | Q35: starr8@rocketmail.com | R35: 1.35 | S35: 16.34 | U35: 0
A36: 45893 | B36: HS-SP-PLD-1A | C36: Spathiphyllum Peace Lily Domino | D36: 2.5 | E36: 3.75 | J36: Status Pending | L36: 6ZZ49C | M36: 1 | N36: 0 | O36: 0 | P36: 1 | Q36: starr8@rocketmail.com | R36: 0 | S36: 2.5 | U36: 0 | V36: 3.75
A37: 45893 | B37: HS-SP-PLD-1E | C37: Spathiphyllum Peace Lily Domino | D37: 2.5 | E37: 3.75 | J37: Status Pending | L37: 1CSDUP | M37: 1 | N37: 0 | O37: 0 | P37: 1 | Q37: starr8@rocketmail.com | R37: 0.5 | S37: 3 | U37: 5 | V37: 8.75
A38: 45893 | B38: HS-BE-AW-1C | C38: Begonia Angel Wing | D38: 0 | E38: 0 | J38: Status Pending | L38: 4G22U5 | M38: 1 | N38: 0 | O38: 0 | P38: 1 | Q38: starr8@rocketmail.com | R38: 1.42 | S38: 1.42 | U38: 0
A39: 45893 | B39: FMY-CA-MA-1D | C39: Calathea Makoyana | D39: 3.33 | E39: 2.83 | J39: Status Pending | L39: C7QOSP | M39: 1 | N39: 0 | O39: 0 | P39: 1 | Q39: starr8@rocketmail.com | R39: 0.5 | S39: 3.83 | U39: 5 | V39: 7.83
A40: 45893 | B40: FMY-CA-MA-1G | C40: Calathea Makoyana | D40: 3.33 | E40: 2.83 | J40: Status Pending | L40: EN413Y | M40: 1 | N40: 0 | O40: 0 | P40: 1 | Q40: starr8@rocketmail.com | R40: 0.67 | S40: 4 | U40: 0 | V40: 2.83
A41: 45893 | B41: FMY-CA-MA-1H | C41: Calathea Makoyana | D41: 3.33 | E41: 2.83 | J41: Status Pending | L41: Q2YSXQ | M41: 1 | N41: 0 | O41: 0 | P41: 1 | Q41: starr8@rocketmail.com | R41: 0.67 | S41: 4 | U41: 0 | V41: 2.83
...

Sheet  PRICING
F1: =SUM(F3:F3005) -> 5645.0427 | G1: =SUM(G3:G3005) -> 0 | H1: =SUM(H3:H3005) -> 0 | I1: =SUM(I3:I3005) -> 0 | J1: =SUM(J3:J3005) -> 69 | K1: =SUM(K3:K3005) -> 691 | M1: =SUM(M3:M3005) -> 750 | N1: =IF(SUM(J3:J992)=0,0,SUM(M3:M992)/SUM(J3:J992)) -> 10.869565
A2: Date | B2: SKU | C2: Product Name | E2: Pot SKU | F2: Pl Co | G2: Pot/Prod Co | H2: OH | I2: Tot Co | J2: Est. Sell Pr | K2: AcSell Pr | L2: Disc | M2: Profit | N2: Margin | O2: Av. Qty | P2: Status | Q2: Notes | R2: Mirror UID | S2: MSRP | T2: Not UID | V2: U ID
A3: {=IF(B3:B3000="","", VLOOKUP( B3:B3000, { TRIM('PLANT Intake Coding'!F3:F1000), 'PLANT Intake Coding'!A3:A1000; TRIM('Transplant Log'!H3:H997), 'Transplant Log'!A3:A997; TRIM('PRODUCT Intake Coding'!I3:I993), 'PRODUCT Intake Coding'!A3:A993 }, 2, FALSE ) )} -> 38202 | B3: =IFERROR(__xludf.DUMMYFUNCTION("ARRAYFORMULA( UNIQUE( FILTER( { UPPER(TRIM(CLEAN(SUBSTITUTE('PLANT Intake Coding'!F3:INDEX('PLANT Intake Coding'!F:F, MATCH(2,1/('PLANT Intake Coding'!F:F<>""""))), CHAR(160), """")))); UPPER(TRIM(CLEAN(SUBSTITUTE('Transplant L"&"og'!H3:INDEX('Transplant Log'!H:H, MATCH(2,1/('Transplant Log'!H:H<>""""))), CHAR(160), """")))); UPPER(TRIM(CLEAN(SUBSTITUTE('PRODUCT Intake Coding'!I3:INDEX('PRODUCT Intake Coding'!I:I, MATCH(2,1/('PRODUCT Intake Coding'!I:I<>""""))), CHAR(160),"&" """")))) }, LEN({ TRIM(CLEAN(SUBSTITUTE('PLANT Intake Coding'!F3:INDEX('PLANT Intake Coding'!F:F, MATCH(2,1/('PLANT Intake Coding'!F:F<>""""))), CHAR(160), """"))); TRIM(CLEAN(SUBSTITUTE('Transplant Log'!H3:INDEX('Transplant L"&"og'!H:H, MATCH(2,1/('Transplant Log'!H:H<>""""))), CHAR(160), """"))); TRIM(CLEAN(SUBSTITUTE('PRODUCT Intake Coding'!I3:INDEX('PRODUCT Intake Coding'!I:I, MATCH(2,1/('PRODUCT Intake Coding'!I:I<>""""))), CHAR(160), """"))) }) ) ) ) "),"HS-BE-AW-1A") -> HS-BE-AW-1A | C3: Angel Wing | E3: =IFERROR(__xludf.DUMMYFUNCTION("ARRAYFORMULA( IF(B3:B3000="""","""", IFNA( VLOOKUP(B3:B3000, FILTER({'Transplant Log'!H3:H997,'Transplant Log'!F3:F997}, LEN('Transplant Log'!H3:H997)), 2, FALSE), IF(COUNTIF('PRODUC"&"T Intake Coding'!I3:I993,B3:B3000), B3:B3000, """") ) ) ) "),"TO-PO-4-MU-1") -> TO-PO-4-MU-1 | F3: {=IF(B3:B3001="","", IFNA( VLOOKUP(B3:B3001, {'Transplant Log'!H3:H997,'Transplant Log'!I3:I997}, 2, FALSE), IFNA( VLOOKUP(B3:B3001, {'PLANT Intake Coding'!F3:F1000,'PLANT Intake Coding'!G3:G1000}, 2, FALSE), 0 ) ) )} -> 0 | L3: None | M3: {=IF(B3:B992="","", IF( (LEN(J3:J992)=0)*(LEN(K3:K992)=0),"", (IF( N(K3:K992)>0, N(K3:K992), N(J3:J992) ) - I3:I992 - IFERROR(N(L3:L992),0) ) ) )} | N3: =IFERROR(__xludf.DUMMYFUNCTION("ARRAYFORMULA( IF(LEN(I3:I3001)=0,"""", IF(LEN(K3:K3001), IFERROR((TO_PURE_NUMBER(K3:K3001)-TO_PURE_NUMBER(I3:I3001))/TO_PURE_NUMBER(K3:K3001),""""), IFERROR((TO_PURE_NUMBER(J3:J3001)-TO_PURE_NUMBER(I3:I3001))/TO_PURE_NUMBER(J3:J3001),"""") ) "&" ) )"),"") | P3: Not for Sale | R3: {=IF(B3:B3000="","", IFERROR( VLOOKUP( B3:B3000, { TRIM('PLANT Intake Coding'!F3:F1000), 'PLANT Intake Coding'!J3:J1000; TRIM('Transplant Log'!H3:H997), 'Transplant Log'!K3:K997; TRIM('PRODUCT Intake Coding'!I3:I993), 'PRODUCT Intake Coding'!P3:P993 }, 2, FALSE ), "" ) )} -> E87921 | S3: {=IF(R3:R3000="","", IFNA( VLOOKUP( R3:R3000, {'PLANT Intake Coding'!$J$3:$J$1000,'PLANT Intake Coding'!$K$3:$K$1000}, 2, FALSE ), "" ) )} | T3: AF49E2 | V3: AF49E2
B4: =IFERROR(__xludf.DUMMYFUNCTION("""COMPUTED_VALUE"""),"HS-PO-GO-1A") -> HS-PO-GO-1A | E4: =IFERROR(__xludf.DUMMYFUNCTION("""COMPUTED_VALUE"""),"") | F4: 0 | L4: Giveaway | N4: =IFERROR(__xludf.DUMMYFUNCTION("""COMPUTED_VALUE"""),"") | R4: 9C3687 | T4: AE5AD3 | V4: AE5AD3
B5: =IFERROR(__xludf.DUMMYFUNCTION("""COMPUTED_VALUE"""),"HS-PH-HL-1A") -> HS-PH-HL-1A | E5: =IFERROR(__xludf.DUMMYFUNCTION("""COMPUTED_VALUE"""),"") | F5: 0 | L5: None | N5: =IFERROR(__xludf.DUMMYFUNCTION("""COMPUTED_VALUE"""),"") | R5: 851D91 | T5: 29FB31 | V5: 29FB31
B6: =IFERROR(__xludf.DUMMYFUNCTION("""COMPUTED_VALUE"""),"HS-PH-BRL-1A") -> HS-PH-BRL-1A | E6: =IFERROR(__xludf.DUMMYFUNCTION("""COMPUTED_VALUE"""),"GA-PO-6-MU-1") -> GA-PO-6-MU-1 | F6: 0 | L6: None | N6: =IFERROR(__xludf.DUMMYFUNCTION("""COMPUTED_VALUE"""),"") | P6: Not for Sale | R6: FB20D8 | T6: 0649C0 | V6: 0649C0
B7: =IFERROR(__xludf.DUMMYFUNCTION("""COMPUTED_VALUE"""),"HS-PI-PEP-1A") -> HS-PI-PEP-1A | E7: =IFERROR(__xludf.DUMMYFUNCTION("""COMPUTED_VALUE"""),"") | F7: 0 | L7: None | N7: =IFERROR(__xludf.DUMMYFUNCTION("""COMPUTED_VALUE"""),"") | R7: 62867D | T7: FE0A2D | V7: FE0A2D
A8: 45899 | B8: =IFERROR(__xludf.DUMMYFUNCTION("""COMPUTED_VALUE"""),"HS-CT-BM-1A") -> HS-CT-BM-1A | E8: =IFERROR(__xludf.DUMMYFUNCTION("""COMPUTED_VALUE"""),"ZO-PO-4-WL-1") -> ZO-PO-4-WL-1 | F8: 0 | N8: =IFERROR(__xludf.DUMMYFUNCTION("""COMPUTED_VALUE"""),"") | R8: 59D755 | T8: 475931 | V8: 475931
B9: =IFERROR(__xludf.DUMMYFUNCTION("""COMPUTED_VALUE"""),"HS-DR-SP-1A") -> HS-DR-SP-1A | E9: =IFERROR(__xludf.DUMMYFUNCTION("""COMPUTED_VALUE"""),"TE-PO-4-MU-3") -> TE-PO-4-MU-3 | F9: 0 | N9: =IFERROR(__xludf.DUMMYFUNCTION("""COMPUTED_VALUE"""),"") | R9: D10239 | T9: 2FF9FD | V9: 2FF9FD
A10: 45873 | B10: =IFERROR(__xludf.DUMMYFUNCTION("""COMPUTED_VALUE"""),"FM-PH-WK-1A") -> FM-PH-WK-1A | E10: =IFERROR(__xludf.DUMMYFUNCTION("""COMPUTED_VALUE"""),"") | F10: 15 | N10: =IFERROR(__xludf.DUMMYFUNCTION("""COMPUTED_VALUE"""),"") | P10: Not for Sale | R10: 8F306F | S10: 0 | T10: 16487D | V10: 16487D
A11: 45872 | B11: =IFERROR(__xludf.DUMMYFUNCTION("""COMPUTED_VALUE"""),"WM-PH-WK-1A") -> WM-PH-WK-1A | E11: =IFERROR(__xludf.DUMMYFUNCTION("""COMPUTED_VALUE"""),"MU-PO-4-WH-1") -> MU-PO-4-WH-1 | F11: 4.9925 | N11: =IFERROR(__xludf.DUMMYFUNCTION("""COMPUTED_VALUE"""),"") | R11: 3A0A52 | T11: A73945 | V11: A73945
B12: =IFERROR(__xludf.DUMMYFUNCTION("""COMPUTED_VALUE"""),"WM-MA-PE-1A") -> WM-MA-PE-1A | C12: White Knight | E12: =IFERROR(__xludf.DUMMYFUNCTION("""COMPUTED_VALUE"""),"") | F12: 7 | K12: 10 | M12: 10 | N12: =IFERROR(__xludf.DUMMYFUNCTION("""COMPUTED_VALUE"""),"") | P12: Sold | R12: C7E314 | T12: 075DBF | V12: 075DBF
A13: 45873 | B13: =IFERROR(__xludf.DUMMYFUNCTION("""COMPUTED_VALUE"""),"TLC-PH-CS-1A") -> TLC-PH-CS-1A | E13: =IFERROR(__xludf.DUMMYFUNCTION("""COMPUTED_VALUE"""),"") | F13: 0 | N13: =IFERROR(__xludf.DUMMYFUNCTION("""COMPUTED_VALUE"""),"") | P13: Damaged | R13: AA4996 | T13: CE10E3 | V13: CE10E3
A14: 45874 | B14: =IFERROR(__xludf.DUMMYFUNCTION("""COMPUTED_VALUE"""),"TAG-AO-DR-1A") -> TAG-AO-DR-1A | E14: =IFERROR(__xludf.DUMMYFUNCTION("""COMPUTED_VALUE"""),"ST-PO-6-NU-1") -> ST-PO-6-NU-1 | F14: 0 | N14: =IFERROR(__xludf.DUMMYFUNCTION("""COMPUTED_VALUE"""),"") | R14: B16039 | T14: F68623 | V14: F68623
A15: 45880 | B15: =IFERROR(__xludf.DUMMYFUNCTION("""COMPUTED_VALUE"""),"FMY-PH-GC-1A") -> FMY-PH-GC-1A | E15: =IFERROR(__xludf.DUMMYFUNCTION("""COMPUTED_VALUE"""),"NR-PO-8-BP-1") -> NR-PO-8-BP-1 | F15: 16.99 | N15: =IFERROR(__xludf.DUMMYFUNCTION("""COMPUTED_VALUE"""),"") | R15: 4546BE | T15: 118596 | V15: 118596
A16: 45880 | B16: =IFERROR(__xludf.DUMMYFUNCTION("""COMPUTED_VALUE"""),"FMY-AL-RSD-1A") -> FMY-AL-RSD-1A | E16: =IFERROR(__xludf.DUMMYFUNCTION("""COMPUTED_VALUE"""),"") | F16: 10.99 | N16: =IFERROR(__xludf.DUMMYFUNCTION("""COMPUTED_VALUE"""),"") | R16: 5DCD93 | T16: EEA2A8 | V16: EEA2A8
A17: 45880 | B17: =IFERROR(__xludf.DUMMYFUNCTION("""COMPUTED_VALUE"""),"FMY-AL-GVF-1A") -> FMY-AL-GVF-1A | E17: =IFERROR(__xludf.DUMMYFUNCTION("""COMPUTED_VALUE"""),"DT-PO-3-GL-1") -> DT-PO-3-GL-1 | F17: 10.99 | N17: =IFERROR(__xludf.DUMMYFUNCTION("""COMPUTED_VALUE"""),"") | R17: 66B4DB | T17: CEB6EA | V17: CEB6EA
A18: 45880 | B18: =IFERROR(__xludf.DUMMYFUNCTION("""COMPUTED_VALUE"""),"FMY-MA-DE-1A") -> FMY-MA-DE-1A | E18: =IFERROR(__xludf.DUMMYFUNCTION("""COMPUTED_VALUE"""),"WO-PO-6-WH-1") -> WO-PO-6-WH-1 | F18: 2.198 | N18: =IFERROR(__xludf.DUMMYFUNCTION("""COMPUTED_VALUE"""),"") | R18: D764EE | S18: 25 | T18: 9652DA | V18: 9652DA
A19: 45880 | B19: =IFERROR(__xludf.DUMMYFUNCTION("""COMPUTED_VALUE"""),"FMY-MA-DE-1A-2") -> FMY-MA-DE-1A-2 | E19: =IFERROR(__xludf.DUMMYFUNCTION("""COMPUTED_VALUE"""),"ST-PO-6-NU-1") -> ST-PO-6-NU-1 | F19: 9.995 | N19: =IFERROR(__xludf.DUMMYFUNCTION("""COMPUTED_VALUE"""),"") | R19: BA6B4C | T19: 64F929 | V19: 64F929
A20: 45880 | B20: =IFERROR(__xludf.DUMMYFUNCTION("""COMPUTED_VALUE"""),"TLC-SC-SS-1A") -> TLC-SC-SS-1A | E20: =IFERROR(__xludf.DUMMYFUNCTION("""COMPUTED_VALUE"""),"TE-PO-4-MU-1") -> TE-PO-4-MU-1 | F20: 1 | N20: =IFERROR(__xludf.DUMMYFUNCTION("""COMPUTED_VALUE"""),"") | P20: Not for Sale | R20: 1DD88F | T20: 339469 | V20: 339469
A21: 45870 | B21: =IFERROR(__xludf.DUMMYFUNCTION("""COMPUTED_VALUE"""),"MMP-MA-AD-1A") -> MMP-MA-AD-1A | E21: =IFERROR(__xludf.DUMMYFUNCTION("""COMPUTED_VALUE"""),"NR-PO-3-BP-1") -> NR-PO-3-BP-1 | F21: 1 | N21: =IFERROR(__xludf.DUMMYFUNCTION("""COMPUTED_VALUE"""),"") | P21: Not for Sale | R21: D78BB8 | T21: 6D8F4B | V21: 6D8F4B
A22: 45866 | B22: =IFERROR(__xludf.DUMMYFUNCTION("""COMPUTED_VALUE"""),"OLN-MA-AD-1A") -> OLN-MA-AD-1A | E22: =IFERROR(__xludf.DUMMYFUNCTION("""COMPUTED_VALUE"""),"NR-PO-3-BP-1") -> NR-PO-3-BP-1 | F22: 3.66 | N22: =IFERROR(__xludf.DUMMYFUNCTION("""COMPUTED_VALUE"""),"") | P22: Not for Sale | R22: DB15AC | T22: 15A7A1 | V22: 15A7A1
A23: 45866 | B23: =IFERROR(__xludf.DUMMYFUNCTION("""COMPUTED_VALUE"""),"OLN-PH-WP-1A") -> OLN-PH-WP-1A | E23: =IFERROR(__xludf.DUMMYFUNCTION("""COMPUTED_VALUE"""),"ST-PO-3-NU-1") -> ST-PO-3-NU-1 | F23: 3.66 | N23: =IFERROR(__xludf.DUMMYFUNCTION("""COMPUTED_VALUE"""),"") | P23: Not for Sale | R23: 1A5668 | T23: 0EC505 | V23: 0EC505
A24: 45866 | B24: =IFERROR(__xludf.DUMMYFUNCTION("""COMPUTED_VALUE"""),"OLN-ALT-PT-1A") -> OLN-ALT-PT-1A | E24: =IFERROR(__xludf.DUMMYFUNCTION("""COMPUTED_VALUE"""),"TO-PO-4-MU-1") -> TO-PO-4-MU-1 | F24: 9.99 | N24: =IFERROR(__xludf.DUMMYFUNCTION("""COMPUTED_VALUE"""),"") | P24: Not for Sale | R24: 30FC62 | T24: 33162E | V24: 33162E
A25: 45866 | B25: =IFERROR(__xludf.DUMMYFUNCTION("""COMPUTED_VALUE"""),"OLN-FI-RF-1A") -> OLN-FI-RF-1A | E25: =IFERROR(__xludf.DUMMYFUNCTION("""COMPUTED_VALUE"""),"") | F25: 3.66 | N25: =IFERROR(__xludf.DUMMYFUNCTION("""COMPUTED_VALUE"""),"") | P25: Not for Sale | R25: C4919B | T25: FF7881 | V25: FF7881
A26: 45902 | B26: =IFERROR(__xludf.DUMMYFUNCTION("""COMPUTED_VALUE"""),"OLN-PH-STS-1A") -> OLN-PH-STS-1A | E26: =IFERROR(__xludf.DUMMYFUNCTION("""COMPUTED_VALUE"""),"WO-PO-6-WH-1") -> WO-PO-6-WH-1 | F26: 52 | N26: =IFERROR(__xludf.DUMMYFUNCTION("""COMPUTED_VALUE"""),"") | P26: Not for Sale | R26: DD2EF3 | T26: 39BA9D | V26: 39BA9D
A27: 45902 | B27: =IFERROR(__xludf.DUMMYFUNCTION("""COMPUTED_VALUE"""),"OLN-PH-SD-1A") -> OLN-PH-SD-1A | E27: =IFERROR(__xludf.DUMMYFUNCTION("""COMPUTED_VALUE"""),"AN-PO-3-MU-1") -> AN-PO-3-MU-1 | F27: 16 | N27: =IFERROR(__xludf.DUMMYFUNCTION("""COMPUTED_VALUE"""),"") | P27: Not for Sale | R27: A09A6D | T27: CD2664 | V27: CD2664
A28: 45871 | B28: =IFERROR(__xludf.DUMMYFUNCTION("""COMPUTED_VALUE"""),"AR-PH-WP-1A") -> AR-PH-WP-1A | E28: =IFERROR(__xludf.DUMMYFUNCTION("""COMPUTED_VALUE"""),"TE-PO-4-MU-1") -> TE-PO-4-MU-1 | F28: 20.4 | N28: =IFERROR(__xludf.DUMMYFUNCTION("""COMPUTED_VALUE"""),"") | P28: Not for Sale | R28: F323DF | T28: 357C92 | V28: 357C92
A29: 45871 | B29: =IFERROR(__xludf.DUMMYFUNCTION("""COMPUTED_VALUE"""),"AR-AL-LM-1A") -> AR-AL-LM-1A | C29: White Princess | E29: =IFERROR(__xludf.DUMMYFUNCTION("""COMPUTED_VALUE"""),"MA-PO-3-SW-1") -> MA-PO-3-SW-1 | F29: 18.9 | N29: =IFERROR(__xludf.DUMMYFUNCTION("""COMPUTED_VALUE"""),"") | P29: Not for Sale | R29: D4D950 | T29: F8821D | V29: F8821D
A30: 45877 | B30: =IFERROR(__xludf.DUMMYFUNCTION("""COMPUTED_VALUE"""),"ZB-SE-HA-1A") -> ZB-SE-HA-1A | C30: Longiloba Mint | E30: =IFERROR(__xludf.DUMMYFUNCTION("""COMPUTED_VALUE"""),"ST-PO-6-NU-1") -> ST-PO-6-NU-1 | F30: 0 | N30: =IFERROR(__xludf.DUMMYFUNCTION("""COMPUTED_VALUE"""),"") | P30: Not for Sale | R30: D8F201 | T30: 695EB4 | V30: 695EB4
A31: 45878 | B31: =IFERROR(__xludf.DUMMYFUNCTION("""COMPUTED_VALUE"""),"IST-PH-PP-1A") -> IST-PH-PP-1A | E31: =IFERROR(__xludf.DUMMYFUNCTION("""COMPUTED_VALUE"""),"MU-PO-4-WH-1") -> MU-PO-4-WH-1 | F31: 10.8 | N31: =IFERROR(__xludf.DUMMYFUNCTION("""COMPUTED_VALUE"""),"") | R31: B46EF4 | T31: 5ECFB2 | V31: 5ECFB2
A32: 45878 | B32: =IFERROR(__xludf.DUMMYFUNCTION("""COMPUTED_VALUE"""),"IST-PH-GCN-1A") -> IST-PH-GCN-1A | E32: =IFERROR(__xludf.DUMMYFUNCTION("""COMPUTED_VALUE"""),"TE-PO-4-MU-1") -> TE-PO-4-MU-1 | F32: 25 | N32: =IFERROR(__xludf.DUMMYFUNCTION("""COMPUTED_VALUE"""),"") | P32: Not for Sale | R32: F3374E | T32: 6AB8A0 | V32: 6AB8A0
A33: 45882 | B33: =IFERROR(__xludf.DUMMYFUNCTION("""COMPUTED_VALUE"""),"TGG-HO-GF-1A") -> TGG-HO-GF-1A | E33: =IFERROR(__xludf.DUMMYFUNCTION("""COMPUTED_VALUE"""),"NR-PO-3-TBP-1") -> NR-PO-3-TBP-1 | F33: 0 | N33: =IFERROR(__xludf.DUMMYFUNCTION("""COMPUTED_VALUE"""),"") | P33: Not for Sale | R33: 1E3D42 | T33: 77D375 | V33: 77D375
A34: 45882 | B34: =IFERROR(__xludf.DUMMYFUNCTION("""COMPUTED_VALUE"""),"TGG-HO-PU-1A") -> TGG-HO-PU-1A | E34: =IFERROR(__xludf.DUMMYFUNCTION("""COMPUTED_VALUE"""),"NR-PO-3-BP-1") -> NR-PO-3-BP-1 | F34: 5 | N34: =IFERROR(__xludf.DUMMYFUNCTION("""COMPUTED_VALUE"""),"") | P34: Not for Sale | R34: C41DCD | T34: 014884 | V34: 014884
A35: 45886 | B35: =IFERROR(__xludf.DUMMYFUNCTION("""COMPUTED_VALUE"""),"FM-MA-DE-1A") -> FM-MA-DE-1A | E35: =IFERROR(__xludf.DUMMYFUNCTION("""COMPUTED_VALUE"""),"") | F35: 5 | N35: =IFERROR(__xludf.DUMMYFUNCTION("""COMPUTED_VALUE"""),"") | P35: Not for Sale | R35: BC6E95 | S35: 0 | T35: 347F64 | V35: 347F64
A36: 45882 | B36: =IFERROR(__xludf.DUMMYFUNCTION("""COMPUTED_VALUE"""),"AM-PH-PP-1A") -> AM-PH-PP-1A | E36: =IFERROR(__xludf.DUMMYFUNCTION("""COMPUTED_VALUE"""),"MU-PO-4-WH-1") -> MU-PO-4-WH-1 | F36: 10.25 | N36: =IFERROR(__xludf.DUMMYFUNCTION("""COMPUTED_VALUE"""),"") | R36: EABB58 | T36: 956D2B | V36: 956D2B
A37: 45882 | B37: =IFERROR(__xludf.DUMMYFUNCTION("""COMPUTED_VALUE"""),"AM-PH-WW-1A") -> AM-PH-WW-1A | C37: Pink Princess | E37: =IFERROR(__xludf.DUMMYFUNCTION("""COMPUTED_VALUE"""),"MU-PO-4-WH-1") -> MU-PO-4-WH-1 | F37: 10.25 | N37: =IFERROR(__xludf.DUMMYFUNCTION("""COMPUTED_VALUE"""),"") | R37: A7877B | T37: B8CD1C | V37: B8CD1C
A38: 45882 | B38: =IFERROR(__xludf.DUMMYFUNCTION("""COMPUTED_VALUE"""),"AM-PH-GL-1A") -> AM-PH-GL-1A | C38: White Wizard | E38: =IFERROR(__xludf.DUMMYFUNCTION("""COMPUTED_VALUE"""),"ZO-PO-4-WL-1") -> ZO-PO-4-WL-1 | F38: 10.25 | N38: =IFERROR(__xludf.DUMMYFUNCTION("""COMPUTED_VALUE"""),"") | R38: 367351 | T38: F99298 | V38: F99298
A39: 45882 | B39: =IFERROR(__xludf.DUMMYFUNCTION("""COMPUTED_VALUE"""),"AM-PH-BI-1A") -> AM-PH-BI-1A | C39: Gloriosum | E39: =IFERROR(__xludf.DUMMYFUNCTION("""COMPUTED_VALUE"""),"ZO-PO-4-WL-1") -> ZO-PO-4-WL-1 | F39: 3.4166667 | N39: =IFERROR(__xludf.DUMMYFUNCTION("""COMPUTED_VALUE"""),"") | R39: EBE164 | T39: EEAE97 | V39: EEAE97
A40: 45881 | B40: =IFERROR(__xludf.DUMMYFUNCTION("""COMPUTED_VALUE"""),"TGOPS-PH-PPM-1A") -> TGOPS-PH-PPM-1A | C40: Birkin | E40: =IFERROR(__xludf.DUMMYFUNCTION("""COMPUTED_VALUE"""),"TE-PO-4-MU-1") -> TE-PO-4-MU-1 | F40: 16.19 | L40: Donation | N40: =IFERROR(__xludf.DUMMYFUNCTION("""COMPUTED_VALUE"""),"") | P40: Available | R40: 3EF9AE | S40: 26.99 | T40: 59E874 | V40: 59E874
...

Sheet Price KEY
A1: Product Name | B1: Pot Code | C1: Pot Size | D1: Disc | F1: Status
A2: Angel Wing | B2: DV-PO-2-WH-1A | C2: 3" | D2: Giveaway | E2: Sold | F2: For Sale
A3: Hoya Krimson Princess | B3: AN-PO-3-MU-1A | C3: 4" | D3: $5 Off | E3: Pending | F3: Sold
A4: McColley's FInale | B4: YA-PO-2-CL-1A | C4: 4.3" | D4: $10 Off | E4: Hold | F4: Delivered
A5: Monstera Deliciosa | B5: EB-PO-4-DO-1A | C5: 2" | D5: None | E5: Available | F5: Pending Sale
A6: String of Hearts | B6: ZO-PO-4-WL-1A | C6: 6" | D6: Donation | E6: Reserved | F6: Keep
A7: String of Pearls | B7: HY-PO-3-DO-1A | C7: 5.5" | D7: Custom | E7: Not for Sale | F7: Hold
A8: Variegated SOH | E8: Giveaway | F8: Shipped
A9: Variegated SOP | C9: 3.7" | E9: Damaged | F9: Pending Shipping
F10: Dead

Sheet Overhead Expenses
G1: =SUM(G3:G997) -> 8671.21 | H1: =SUM(H3:H997) -> 0 | I1: =SUM(I3:I992) -> 926.58 | J1: =G1 - I1 -> 7744.63 | K1: =SUM(K3:K994) -> 7744.63
A2: Date | B2: Vendor | C2: Brand | D2: Category | E2: Description | F2: Qty | G2: Sub Tot | H2: Ship. | I2: Disc. | J2: Un. Cost | K2: Act. Tot | L2: Pmt. M. | M2: Card # | N2: Invoice # | O2: Notes / Project | P2: U ID | Q2: Owner Email | R2: Receipt
A3: 45941 | B3: TikTok | C3: Rosebud Homegoods | D3: Tools & Supplies | E3: Soil Scoop | F3: 1 | G3: 15 | H3: 0 | I3: 0 | J3: {=IF(F3:F997="","", ROUND( (G3:G997 + H3:H997 - I3:I997) / F3:F997, 2 ) )} -> 15 | K3: {=IF(G3:G994="","", G3:G994 - H3:H994 - I3:I994 )} -> 15 | L3: Credit Card | P3: 3779B1 | Q3: starr8@rocketmail.com
A4: 45874 | B4: Amazon | C4: EnHomee | D4: Shelving/Fixtures | E4: Wooden Plant Stand | F4: 1 | G4: 39.99 | H4: 0 | I4: 39.99 | J4: 0 | K4: 0 | L4: Gift Certificate | P4: 6EF362 | Q4: starr8@rocketmail.com
A5: 45874 | B5: Amazon | C5: Homvana | D5: Climate & Environment | E5: Warm & cool mist humidifier | F5: 1 | G5: 29.98 | I5: 29.98 | J5: 0 | K5: 0 | L5: Gift Certificate | P5: A66D13 | Q5: starr8@rocketmail.com
A6: 45874 | B6: Amazon | C6: Legigo | D6: Soil & Amendments | E6: Orchid bark | F6: 1 | G6: 14.99 | I6: 14.99 | J6: 0 | K6: 0 | L6: Gift Certificate | P6: DDE6C4 | Q6: starr8@rocketmail.com
A7: 45874 | B7: Amazon | C7: Mkono | D7: Propagation Supplies | E7: Plant propagation tube wall hanger | F7: 1 | G7: 24.99 | I7: 24.99 | J7: 0 | K7: 0 | L7: Gift Certificate | P7: 156075 | Q7: starr8@rocketmail.com
A8: 45873 | B8: Amazon | C8: Legigo | D8: Soil & Amendments | E8: sphagnum moss (various sizes) | F8: 1 | G8: 11.39 | I8: 11.39 | J8: 0 | K8: 0 | L8: Gift Certificate | P8: 4CDA26 | Q8: starr8@rocketmail.com
A9: 45879 | B9: Amazon | C9: Yuanling | D9: Labels & Stickers | E9: Plastic plant labels (green/red) | F9: 1 | G9: 5.63 | I9: 0 | J9: 5.63 | K9: 5.63 | L9: Credit Card | M9: 1002 | P9: 8453D7 | Q9: starr8@rocketmail.com
A10: 45879 | B10: Amazon | C10: Yuanling | D10: Labels & Stickers | E10: Plastic plant labels (green/red) | F10: 1 | G10: 5.63 | I10: 0 | J10: 5.63 | K10: 5.63 | L10: Credit Card | M10: 1002 | P10: BBCD88 | Q10: starr8@rocketmail.com
A11: 45880 | B11: Amazon | C11: TDHDIKE | D11: Labels & Stickers | E11: Plastic plant labels (white) | F11: 1 | G11: 11.99 | I11: 0 | J11: 11.99 | K11: 11.99 | L11: Credit Card | M11: 1002 | P11: F34739 | Q11: starr8@rocketmail.com
A12: 45877 | B12: Amazon | C12: SupKing | D12: Propagation Supplies | E12: Air layering propagation pods | F12: 1 | G12: 7.59 | I12: 2.28 | J12: 5.31 | K12: 5.31 | L12: Credit Card | M12: 1002 | P12: 2AC0EA | Q12: starr8@rocketmail.com
A13: 45877 | B13: Amazon | C13: HNXTYAOB | D13: Tools & Supplies | E13: Repotting mats (large) | F13: 1 | G13: 28.99 | I13: 0 | J13: 28.99 | K13: 28.99 | L13: Credit Card | M13: 1002 | P13: 623A9B | Q13: starr8@rocketmail.com
A14: 45877 | B14: Amazon | C14: Voulosimi | D14: Soil & Amendments | E14: 30 QT Perlite | F14: 1 | G14: 36.99 | I14: 0 | J14: 36.99 | K14: 36.99 | L14: Credit Card | M14: 1002 | P14: 99B44C | Q14: starr8@rocketmail.com
A15: 45877 | B15: Amazon | C15: SupKing | D15: Propagation Supplies | E15: Air layering propagation pods | F15: 1 | G15: 7.59 | I15: 0 | J15: 7.59 | K15: 7.59 | L15: Credit Card | M15: 1002 | P15: D12DFD | Q15: starr8@rocketmail.com
A16: 45877 | B16: Amazon | C16: TPS NUTRIENTS | D16: Treatments & Fertilizers | E16: Silica plant supplement | F16: 1 | G16: 9.99 | I16: 0 | J16: 9.99 | K16: 9.99 | L16: Credit Card | M16: 1002 | P16: 08A7AE | Q16: starr8@rocketmail.com
A17: 45877 | B17: Amazon | C17: Legigo | D17: Soil & Amendments | E17: sphagnum moss (various sizes) | F17: 1 | G17: 39.89 | I17: 0 | J17: 39.89 | K17: 39.89 | L17: Credit Card | M17: 1002 | P17: 40215F | Q17: starr8@rocketmail.com
A18: 45877 | B18: Amazon | C18: Technaflora | D18: Propagation Supplies | E18: Rootech rooting gel | F18: 1 | G18: 6.63 | I18: 0 | J18: 6.63 | K18: 6.63 | L18: Credit Card | M18: 1002 | P18: 779B10 | Q18: starr8@rocketmail.com
A19: 45877 | B19: Amazon | C19: ferti-lome | D19: Treatments & Fertilizers | E19: Houseplant fertilizer | F19: 1 | G19: 12.77 | J19: 12.77 | K19: 12.77 | L19: Credit Card | M19: 1002 | P19: AF14C1 | Q19: starr8@rocketmail.com
A20: 45877 | B20: Amazon | C20: RWNTAO | D20: Lighting | E20: LED grow light bar set | F20: 1 | G20: 22.79 | J20: 22.79 | K20: 22.79 | L20: Credit Card | M20: 1002 | P20: E68E72 | Q20: starr8@rocketmail.com
A21: 45877 | B21: Amazon | C21: Barrina | D21: Shelving/Fixtures | E21: Heavy duty wire shelving rack w/ lights | F21: 1 | G21: 234.99 | J21: 234.99 | K21: 234.99 | L21: Credit Card | M21: 1002 | P21: 1E0823 | Q21: starr8@rocketmail.com
A22: 45877 | B22: Amazon | C22: Legigo | D22: Soil & Amendments | E22: Orchid bark | F22: 1 | G22: 28.99 | J22: 28.99 | K22: 28.99 | L22: Credit Card | M22: 1002 | P22: 5581D4 | Q22: starr8@rocketmail.com
A23: 45879 | B23: Amazon | C23: Govee | D23: Climate & Environment | E23: Bluetooth hygrometers | F23: 1 | G23: 29.74 | J23: 29.74 | K23: 29.74 | L23: Credit Card | M23: 1002 | P23: 8CFB85 | Q23: starr8@rocketmail.com
A24: 45879 | B24: Amazon | C24: JRD | D24: Climate & Environment | E24: Warm & cool mist humidifier | F24: 1 | G24: 79.99 | I24: 30 | J24: 49.99 | K24: 49.99 | L24: Credit Card | M24: 1002 | P24: C47536 | Q24: starr8@rocketmail.com
A25: 45881 | B25: Amazon | C25: Luxbird | D25: Climate & Environment | E25: Seedling heat mats with thermostat | F25: 1 | G25: 53.59 | J25: 53.59 | K25: 53.59 | L25: Credit Card | M25: 1002 | P25: FBEEE7 | Q25: starr8@rocketmail.com
A26: 45881 | B26: Amazon | C26: RWNTAO | D26: Lighting | E26: LED grow light bar set | F26: 1 | G26: 22.79 | I26: 2.28 | J26: 20.51 | K26: 20.51 | L26: Credit Card | M26: 1002 | P26: 336898 | Q26: starr8@rocketmail.com
A27: 45884 | B27: Amazon | C27: Avery | D27: Labels & Stickers | E27: Waterproof rectangle labels | F27: 1 | G27: 39.3 | I27: 0 | J27: 39.3 | K27: 39.3 | L27: Credit Card | M27: 1002 | P27: 6AE249 | Q27: starr8@rocketmail.com
A28: 45884 | B28: Amazon | C28: Cubic Coating | D28: Labels & Stickers | E28: Custom waterproof vinyl stickers | F28: 1 | G28: 7.99 | I28: 0 | J28: 7.99 | K28: 7.99 | L28: Credit Card | M28: 1002 | P28: A25BFA | Q28: starr8@rocketmail.com
A29: 45884 | B29: Amazon | C29: WOWBOX | D29: Tools & Supplies | E29: Clear drawer organizer set | F29: 1 | G29: 17.99 | I29: 0 | J29: 17.99 | K29: 17.99 | L29: Credit Card | M29: 1002 | P29: D9D5AB | Q29: starr8@rocketmail.com
A30: 45884 | B30: Amazon | C30: Us-garden life | D30: Miscellaneous | E30: Yellow sticky fungus gnat traps | F30: 1 | G30: 11.89 | I30: 0 | J30: 11.89 | K30: 11.89 | L30: Credit Card | M30: 1002 | P30: 114F5C | Q30: starr8@rocketmail.com
A31: 45886 | B31: Amazon | C31: Geyoga | D31: Cleaning & Sanitation | E31: Microfiber dusting gloves | F31: 1 | G31: 19.99 | I31: 0 | J31: 19.99 | K31: 19.99 | L31: Credit Card | M31: 1002 | P31: 48C90D | Q31: starr8@rocketmail.com
A32: 45877 | B32: Amazon | C32: MIIIM | D32: Tools & Supplies | E32: Self-watering moss poles | F32: 1 | G32: 26.79 | I32: 0 | J32: 26.79 | K32: 26.79 | L32: Credit Card | M32: 1002 | P32: 8042BE | Q32: starr8@rocketmail.com
A33: 45881 | B33: Faire | C33: The Gay Ole Plant Shop | D33: Inbound Shipping | E33: Live Plants | F33: 9 | G33: 35.53 | I33: 17.5 | J33: 2 | K33: 18.03 | L33: Debit Card | M33: 6116 | N33: Order #A2XS4KRJ22 | P33: B7BC6F | Q33: starr8@rocketmail.com
A34: 45884 | B34: Faire | C34: BWH Plant Company | D34: Inbound Shipping | E34: Live Plants | F34: 20 | G34: 74.17 | I34: 82.5 | J34: -0.42 | K34: -8.33 | L34: Credit Card | M34: 1002 | N34: Order #S77AG59RJX | P34: EF3620 | Q34: starr8@rocketmail.com
A35: 45902 | B35: Faire | C35: Best Plant Friend | D35: Inbound Shipping | E35: Live Plants | F35: 12 | G35: 0 | I35: 19.69 | J35: -1.64 | K35: -19.69 | L35: Credit Card | M35: 5770 | N35: Order #BUCJZSM9TH | P35: 26AFD1 | Q35: starr8@rocketmail.com
A36: 45909 | B36: Faire | C36: Dicks Sticks & Exotics | D36: Inbound Shipping | E36: Live Plants | F36: 37 | G36: 35 | I36: 0 | J36: 0.95 | K36: 35 | L36: Credit Card | M36: 5770 | N36: Order #7634WQK7TQ | P36: 5E2982 | Q36: starr8@rocketmail.com
A37: 45909 | B37: Faire | C37: Arcadia Garden Products | D37: Inbound Shipping | E37: Live Plants | F37: 15 | G37: 62.88 | I37: 40.75 | J37: 1.48 | K37: 22.13 | L37: Credit Card | M37: 5770 | N37: Order #DYZ5SXKCFD | P37: 95A333 | Q37: starr8@rocketmail.com
A38: 45915 | B38: Faire | C38: BWH Plant Company | D38: Inbound Shipping | E38: Live Plants | F38: 26 | G38: 74.8 | I38: 0 | J38: 2.88 | K38: 74.8 | L38: Credit Card | M38: 1002 | N38: Order #6BTFSUN8P3 | P38: CD1CE4 | Q38: starr8@rocketmail.com
A39: 45915 | B39: Faire | C39: Thorsen's Greenhouse | D39: Inbound Shipping | E39: Live Plants | F39: 16 | G39: 0 | I39: 0 | J39: 0 | K39: 0 | L39: Unpaid Invoice | M39: UI | N39: Order #5BQ26SNEMZ | P39: 049695 | Q39: starr8@rocketmail.com
A40: 45920 | B40: Faire | C40: Jungle Club | D40: Inbound Shipping | E40: Planters | F40: 24 | G40: 0 | I40: 0 | J40: 0 | K40: 0 | L40: Unpaid Invoice | M40: UI | N40: Order #92FFNYJ3EJ | P40: 3C1046 | Q40: starr8@rocketmail.com
...

Sheet Overhead KEY
B1: VENDOR | C1: BRAND | D1: CATEGORY | E1: DESCRIPTION | F1: Pmt. Method | G1: Card #
B2: Amazon | C2: AIMFIKIOR | D2: Bags & Packaging | E2: Acrylic brochure holders | F2: ACH | G2: 0590
B3: Dawn W. | C3: Amano Studio | D3: Cash & POS | E3: Acrylic sign holders (multiple sizes) | F3: Credit Card | G3: 1002
B4: Faire | C4: AojSup | D4: Cleaning & Sanitation | E4: Adjustable halo grow lights | F4: Cash | G4: 3150
B5: Fields | C5: Aokrean | D5: Climate & Environment | E5: Air layering propagation pods | F5: Cash App | G5: 5770
B6: Fred Meyer | C6: Arcadia Garden Products | D6: Fuel | E6: Assistant | F6: Other | G6: 6116
B7: Home Depot | C7: Aspamms | D7: Inbound Shipping | E7: Black shade cloth tarp | F7: PayPal | G7: 9565
B8: Palm Street | C8: Aura Rooted | D8: Labels & Stickers | E8: Bluetooth hygrometers | F8: Square | G8: UI
B9: Temu | C9: Avery | D9: Labor | E9: Bonsai pruning scissors | F9: Venmo | G9: 6921
B10: TikTok | C10: Axle Rose Co | D10: Lighting | E10: Castile liquid soap | F10: Zelle
B11: Walmart | C11: Barrina | D11: Market Fees & Supplies | E11: Clear acrylic business card holders | F11: Promotional Credit
C12: Barydat | D12: Office & Admin Supplies | E12: Clear drawer organizer set | F12: Gift Certificate
C13: Berkland | D13: Outbound Shipping | E13: Clear window fly traps | F13: Debit Card
C14: Best Plant Friend | D14: Packing & Shipping | E14: Custom waterproof vinyl stickers | F14: Unpaid Invoice
C15: Bleidruck | D15: Plant Supports | E15: Folding table with adjustable height
C16: Bonide | D16: Plant Tags & Labels | E16: Frosted plastic shelf liners
C17: Brandon The Plant Guy | D17: Professional Services | E17: Glossy photo paper
C18: BWH Plant Company | D18: Propagation Supplies | E18: Glossy white address sticker labels
C19: Dicks Sticks & Exotics | D19: Rent | E19: Half-sheet adhesive shipping labels
C20: Dr. Bronner's | D20: Repairs & Maintenance | E20: Heavy duty shipping tape
C21: Duck | D21: Shade & Protection | E21: Heavy duty wire shelving rack
C22: EnHomee | D22: Shelving/Fixtures | E22: Honeycomb packing paper roll
C23: Epic Medical Supply | D23: Soil & Amendments | E23: Horticultural perlite and vermiculite
C24: EXPO | D24: Stationery & Print | E24: Houseplant fertilizer
C25: Facebook Marketplace | D25: Table Covers & Displays | E25: Hydrogen peroxide (bulk)
C26: Fam Plants | D26: Tables & Furniture | E26: Isopropyl alcohol (bulk)
... C30: gegemaoyi | D30: Uniforms & Workwear | E30: Key Chains
C31: Generic | E31: Kraft paper gift bags with window
C32: Geyoga | E32: Large T-type plastic plant labels
C33: Govee | E33: LED grow light bar set
C34: HIIMIEI | E34: Live plant shipping stickers
C35: HNXTYAOB | E35: Live Plants
C36: Home Stock | E36: Locking cash box
C37: Hometex Canada | E37: Magnetic whiteboard labels
C38: Homvana | E38: Medium T-shape plastic plant tags
C39: It's a Succulent Thang | E39: Microfiber dusting gloves
C40: JRD | E40: Mini acrylic display easels
C41: Jumanji Jon Plants | E41: Mini plastic nursery pots
C42: Jungle Club | E42: Orchid bark
... C73: Technaflora | E73: Heavy duty wire shelving rack w/ lights
...

Sheet Transplant Log
A2: Date | B2: Original SKU | C2: Action | D2: Media | E2: From Pot | F2: To Pot | G2: ID | H2: Division SKU | I2: $ PER | J2: POT COLOR | K2: U ID | L2: Notes | M2: Created At | N2: Owner Email | O2: Add On | P2: Photo | Q2: Plant Name | S2: MSRP
